Workbook

Sheet Champions
C1: Stats
C2: HP | D2: Attack Damage (AD) | E2: Ability Power (AP) | F2: Armor | G2: Magic Resist (MR) | H2: Attack Speed (AS) | I2: Critical Strike Chance | J2: Critical Strike Damage | K2: Omnivamp | L2: Damage Amp. | M2: Durability | O2: AD Scaling | P2: AP Scaling
A3: Champions | B3: Jayce | C3: 450 | D3: 65 | E3: 0 | F3: 20 | G3: 20 | H3: 0.75 | I3: 0.25 | J3: 0 | K3: 0 | L3: 0 | M3: 0 | O3: 0.6 | P3: 0.05
B4: Janna | C4: 300 | D4: 40 | E4: 50 | F4: 10 | G4: 10 | H4: 0.75 | I4: 0.25 | J4: 0 | K4: 0 | L4: 0 | M4: 0 | O4: 0.15 | P4: 0.5
B5: Dr.Mundo | C5: 550 | D5: 45 | E5: 0 | F5: 30 | G5: 25 | H5: 0.65 | I5: 0.25 | J5: 0 | K5: 0 | L5: 0.02 | M5: 0.04 | O5: 0.4 | P5: 0.15
B6: Azir | C6: 300 | D6: 40 | E6: 45 | F6: 15 | G6: 15 | H6: 0.85 | I6: 0.25 | J6: 0 | K6: 0 | L6: 0 | M6: 0 | O6: 0.4 | P6: 0.45
B7: Poppy | C7: 450 | D7: 50 | E7: 0 | F7: 35 | G7: 35 | H7: 0.65 | I7: 0.25 | J7: 0 | K7: 0 | L7: 0 | M7: 0.05 | O7: 0.5 | P7: 0.1
B8: Draven | C8: 350 | D8: 70 | E8: 0 | F8: 10 | G8: 10 | H8: 0.75 | I8: 0.25 | J8: 0 | K8: 0 | L8: 0 | M8: 0 | O8: 0.6 | P8: 0.05
B9: Katarina | C9: 350 | D9: 40 | E9: 55 | F9: 10 | G9: 10 | H9: 0.65 | I9: 0.5 | J9: 0 | K9: 0 | L9: 0 | M9: 0 | O9: 0.35 | P9: 0.55
B10: Kog'Maw | C10: 350 | D10: 40 | E10: 40 | F10: 15 | G10: 15 | H10: 0.85 | I10: 0.25 | J10: 0 | K10: 0 | L10: 0.05 | M10: 0 | O10: 0.45 | P10: 0.45
B11: Seraphine | C11: 450 | D11: 25 | E11: 65 | F11: 10 | G11: 10 | H11: 0.55 | I11: 0.25 | J11: 0 | K11: 0 | L11: 0.06 | M11: 0 | O11: 0.05 | P11: 0.65
B12: Renekton | C12: 450 | D12: 45 | E12: 0 | F12: 20 | G12: 20 | H12: 0.65 | I12: 0.25 | J12: 0 | K12: 0 | L12: 0 | M12: 0 | O12: 0.35 | P12: 0.2
B13: Rakan | C13: 500 | D13: 25 | E13: 35 | F13: 30 | G13: 25 | H13: 0.75 | I13: 0.25 | J13: 0 | K13: 0 | L13: 0 | M13: 0.02 | O13: 0.3 | P13: 0.5
O15: In TFT, the "enemies" are just champions in the enemy team, with other item combinations | Q15: This allows the player to know exactly what he is facing and plan ahead. (Perfect Information)
B16: Champion Type Leyend
C17: Physical Damage (AD)
C18: Magic Damage (AP)
C19: Attack Speed (AS)
C20: Tank Item

Sheet BaseItem
C1: STATS
C2: Health | D2: Attack Damage | E2: Ability Power | F2: Armor | G2: Magic Resist | H2: Attack Speed | I2: Critical Strike Chance | J2: Critical Strike Damage | K2: Omnivamp | L2: Damage Amp. | M2: Durability
B3: Base Item | C3: 0 | D3: 0 | E3: 0 | F3: 0 | G3: 0 | H3: 0 | I3: 0 | J3: 1 | K3: 0 | L3: 0 | M3: 0
C6: Instead of a "Rock, Paper, Scissors" elemental system I decided to go for a buff/ debuff approach that affects Physical Damage, Magic Damage or both)

Sheet Items
D1: Stats
C2: Health | D2: Attack Damage | E2: Ability Power | F2: Armor | G2: Magic Resist | H2: Attack Speed | I2: Critical Strike Chance | J2: Critical Strike Damage | K2: Omnivamp | L2: Damage Amp. | M2: Durability | N2: Index
A3: Items | B3: Spear of Shojin | C3: =BaseItem!$C$3 -> 0 | D3: =BaseItem!$D$3+15 -> 15 | E3: =BaseItem!$E$3+10 -> 10 | F3: =BaseItem!$F$3 -> 0 | G3: =BaseItem!$G$3 -> 0 | H3: =BaseItem!$H$3 -> 0 | I3: =BaseItem!$I$3 -> 0 | J3: =BaseItem!$J$3 -> 1 | K3: =BaseItem!$K$3 -> 0 | L3: =BaseItem!$L$3+10% -> 0.1 | M3: =BaseItem!$M$3 -> 0 | N3: 1
B4: Kraken's Fury | C4: =BaseItem!$C$3 -> 0 | D4: =BaseItem!$D$3+10 -> 10 | E4: =BaseItem!$E$3 -> 0 | F4: =BaseItem!$F$3 -> 0 | G4: =BaseItem!$G$3+20 -> 20 | H4: =BaseItem!$H$3+10% -> 0.1 | I4: =BaseItem!$I$3 -> 0 | J4: =BaseItem!$J$3 -> 1 | K4: =BaseItem!$K$3 -> 0 | L4: =BaseItem!$L$3 -> 0 | M4: =BaseItem!$M$3 -> 0 | N4: 1
B5: Infinity Edge | C5: =BaseItem!$C$3 -> 0 | D5: =BaseItem!$D$3+35 -> 35 | E5: =BaseItem!$E$3 -> 0 | F5: =BaseItem!$F$3 -> 0 | G5: =BaseItem!$G$3 -> 0 | H5: =BaseItem!$H$3 -> 0 | I5: =BaseItem!$I$3+35% -> 0.35 | J5: =BaseItem!$J$3+30% -> 1.3 | K5: =BaseItem!$K$3 -> 0 | L5: =BaseItem!$L$3 -> 0 | M5: =BaseItem!$M$3 -> 0 | N5: 1
B6: Giant Slayer | C6: =BaseItem!$C$3 -> 0 | D6: 20 | E6: =BaseItem!$E$3+20 -> 20 | F6: =BaseItem!$F$3 -> 0 | G6: =BaseItem!$G$3 -> 0 | H6: =BaseItem!$H$3+15% -> 0.15 | I6: =BaseItem!$I$3 -> 0 | J6: =BaseItem!$J$3 -> 1 | K6: =BaseItem!$K$3 -> 0 | L6: =BaseItem!$L$3 -> 0 | M6: =BaseItem!$M$3 -> 0 | N6: 1
B7: Edge of Night | C7: =BaseItem!$C$3 -> 0 | D7: =BaseItem!$D$3+10 -> 10 | E7: =BaseItem!$E$3+10 -> 10 | F7: =BaseItem!$F$3+20 -> 20 | G7: =BaseItem!$G$3 -> 0 | H7: =BaseItem!$H$3+15% -> 0.15 | I7: =BaseItem!$I$3 -> 0 | J7: =BaseItem!$J$3 -> 1 | K7: =BaseItem!$K$3 -> 0 | L7: =BaseItem!$L$3 -> 0 | M7: =BaseItem!$M$3 -> 0 | N7: 1
B8: Deathblade | C8: =BaseItem!$C$3 -> 0 | D8: =BaseItem!$D$3+55 -> 55 | E8: =BaseItem!$E$3 -> 0 | F8: =BaseItem!$F$3 -> 0 | G8: =BaseItem!$G$3 -> 0 | H8: =BaseItem!$H$3 -> 0 | I8: =BaseItem!$I$3 -> 0 | J8: =BaseItem!$J$3 -> 1 | K8: =BaseItem!$K$3 -> 0 | L8: =BaseItem!$L$3+10% -> 0.1 | M8: =BaseItem!$M$3 -> 0 | N8: 1
B9: Bloodthirster | C9: =BaseItem!$C$3 -> 0 | D9: =BaseItem!$D$3+20 -> 20 | E9: =BaseItem!$E$3+20 -> 20 | F9: =BaseItem!$F$3 -> 0 | G9: =BaseItem!$G$3+20 -> 20 | H9: =BaseItem!$H$3 -> 0 | I9: =BaseItem!$I$3 -> 0 | J9: =BaseItem!$J$3 -> 1 | K9: =BaseItem!$K$3+20% -> 0.2 | L9: =BaseItem!$L$3 -> 0 | M9: =BaseItem!$M$3 -> 0 | N9: 1
B10: Morellonomicon | C10: =BaseItem!$C$3+150 -> 150 | D10: =BaseItem!$D$3 -> 0 | E10: =BaseItem!$E$3+25 -> 25 | F10: =BaseItem!$F$3 -> 0 | G10: =BaseItem!$G$3 -> 0 | H10: =BaseItem!$H$3 -> 0 | I10: =BaseItem!$I$3 -> 0 | J10: =BaseItem!$J$3 -> 1 | K10: =BaseItem!$K$3 -> 0 | L10: =BaseItem!$L$3 -> 0 | M10: =BaseItem!$M$3 -> 0 | N10: 2
B11: Void Staff | C11: =BaseItem!$C$3 -> 0 | D11: =BaseItem!$D$3 -> 0 | E11: =BaseItem!$E$3+35 -> 35 | F11: =BaseItem!$F$3 -> 0 | G11: =BaseItem!$G$3 -> 0 | H11: =BaseItem!$H$3+15% -> 0.15 | I11: =BaseItem!$I$3 -> 0 | J11: =BaseItem!$J$3 -> 1 | K11: =BaseItem!$K$3 -> 0 | L11: =BaseItem!$L$3 -> 0 | M11: =BaseItem!$M$3 -> 0 | N11: 2
B12: Blue Buff | C12: =BaseItem!$C$3 -> 0 | D12: =BaseItem!$D$3+15 -> 15 | E12: =BaseItem!$E$3+15 -> 15 | F12: =BaseItem!$F$3 -> 0 | G12: =BaseItem!$G$3 -> 0 | H12: =BaseItem!$H$3 -> 0 | I12: =BaseItem!$I$3 -> 0 | J12: =BaseItem!$J$3 -> 1 | K12: =BaseItem!$K$3 -> 0 | L12: =BaseItem!$L$3 -> 0 | M12: =BaseItem!$M$3 -> 0 | N12: 2
B13: Jewled Gauntlet | C13: =BaseItem!$C$3 -> 0 | D13: =BaseItem!$D$3 -> 0 | E13: =BaseItem!$E$3+35 -> 35 | F13: =BaseItem!$F$3 -> 0 | G13: =BaseItem!$G$3 -> 0 | H13: =BaseItem!$H$3 -> 0 | I13: =BaseItem!$I$3+35% -> 0.35 | J13: =BaseItem!$J$3+30% -> 1.3 | K13: =BaseItem!$K$3 -> 0 | L13: =BaseItem!$L$3 -> 0 | M13: =BaseItem!$M$3 -> 0 | N13: 2
B14: Rabadon's Deathcap | C14: =BaseItem!$C$3 -> 0 | D14: =BaseItem!$D$3 -> 0 | E14: 50 | F14: =BaseItem!$F$3 -> 0 | G14: =BaseItem!$G$3 -> 0 | H14: =BaseItem!$H$3 -> 0 | I14: =BaseItem!$I$3 -> 0 | J14: =BaseItem!$J$3 -> 1 | K14: =BaseItem!$K$3 -> 0 | L14: =BaseItem!$L$3+15% -> 0.15 | M14: =BaseItem!$M$3 -> 0 | N14: 2
B15: Hand of Justice | C15: =BaseItem!$C$3 -> 0 | D15: =BaseItem!$D$3+15 -> 15 | E15: =BaseItem!$E$3+15 -> 15 | F15: =BaseItem!$F$3 -> 0 | G15: =BaseItem!$G$3 -> 0 | H15: =BaseItem!$H$3 -> 0 | I15: =BaseItem!$I$3+20% -> 0.2 | J15: =BaseItem!$J$3 -> 1 | K15: =BaseItem!$K$3+12% -> 0.12 | L15: =BaseItem!$L$3 -> 0 | M15: =BaseItem!$M$3 -> 0 | N15: 2
B16: Arcangel's Staff | C16: =BaseItem!$C$3 -> 0 | D16: =BaseItem!$D$3 -> 0 | E16: 40 | F16: =BaseItem!$F$3 -> 0 | G16: =BaseItem!$G$3 -> 0 | H16: =BaseItem!$H$3 -> 0 | I16: =BaseItem!$I$3 -> 0 | J16: =BaseItem!$J$3 -> 1 | K16: =BaseItem!$K$3+5% -> 0.05 | L16: =BaseItem!$L$3+8% -> 0.08 | M16: =BaseItem!$M$3 -> 0 | N16: 2
B17: Hextech Gunblade | C17: =BaseItem!$C$3 -> 0 | D17: =BaseItem!$D$3+20 -> 20 | E17: =BaseItem!$E$3+20 -> 20 | F17: =BaseItem!$F$3 -> 0 | G17: =BaseItem!$G$3 -> 0 | H17: =BaseItem!$H$3 -> 0 | I17: =BaseItem!$I$3 -> 0 | J17: =BaseItem!$J$3 -> 1 | K17: =BaseItem!$K$3+15% -> 0.15 | L17: =BaseItem!$L$3 -> 0 | M17: =BaseItem!$M$3 -> 0 | N17: 2
B18: Striker's Flail | C18: =BaseItem!$C$3+150 -> 150 | D18: =BaseItem!$D$3 -> 0 | E18: =BaseItem!$E$3 -> 0 | F18: =BaseItem!$F$3 -> 0 | G18: =BaseItem!$G$3 -> 0 | H18: =BaseItem!$H$3+10% -> 0.1 | I18: =BaseItem!$I$3+20% -> 0.2 | J18: =BaseItem!$J$3 -> 1 | K18: =BaseItem!$K$3 -> 0 | L18: =BaseItem!$L$3 -> 0 | M18: =BaseItem!$M$3 -> 0 | N18: 3
B19: Red Buff | C19: =BaseItem!$C$3 -> 0 | D19: =BaseItem!$D$3 -> 0 | E19: =BaseItem!$E$3 -> 0 | F19: =BaseItem!$F$3 -> 0 | G19: =BaseItem!$G$3 -> 0 | H19: =BaseItem!$H$3+45% -> 0.45 | I19: =BaseItem!$I$3 -> 0 | J19: =BaseItem!$J$3 -> 1 | K19: =BaseItem!$K$3 -> 0 | L19: =BaseItem!$L$3+6% -> 0.06 | M19: =BaseItem!$M$3 -> 0 | N19: 3
B20: Nashor's Tooth | C20: =BaseItem!$C$3+150 -> 150 | D20: =BaseItem!$D$3 -> 0 | E20: =BaseItem!$E$3+15 -> 15 | F20: =BaseItem!$F$3 -> 0 | G20: =BaseItem!$G$3 -> 0 | H20: =BaseItem!$H$3+10% -> 0.1 | I20: =BaseItem!$I$3+20% -> 0.2 | J20: =BaseItem!$J$3 -> 1 | K20: =BaseItem!$K$3 -> 0 | L20: =BaseItem!$L$3 -> 0 | M20: =BaseItem!$M$3 -> 0 | N20: 3
B21: Guinsoo's Rageblade | C21: =BaseItem!$C$3 -> 0 | D21: =BaseItem!$D$3 -> 0 | E21: =BaseItem!$E$3+15 -> 15 | F21: =BaseItem!$F$3 -> 0 | G21: =BaseItem!$G$3 -> 0 | H21: =BaseItem!$H$3+25% -> 0.25 | I21: =BaseItem!$I$3 -> 0 | J21: =BaseItem!$J$3 -> 1 | K21: =BaseItem!$K$3 -> 0 | L21: =BaseItem!$L$3 -> 0 | M21: =BaseItem!$M$3 -> 0 | N21: 3
B22: Last Whisper | C22: =BaseItem!$C$3 -> 0 | D22: =BaseItem!$D$3+15 -> 15 | E22: =BaseItem!$E$3 -> 0 | F22: =BaseItem!$F$3 -> 0 | G22: =BaseItem!$G$3 -> 0 | H22: =BaseItem!$H$3+20% -> 0.2 | I22: =BaseItem!$I$3+20% -> 0.2 | J22: =BaseItem!$J$3 -> 1 | K22: =BaseItem!$K$3 -> 0 | L22: =BaseItem!$L$3 -> 0 | M22: =BaseItem!$M$3 -> 0 | N22: 3
B23: Quicksilver | C23: =BaseItem!$C$3 -> 0 | D23: =BaseItem!$D$3 -> 0 | E23: =BaseItem!$E$3 -> 0 | F23: =BaseItem!$F$3 -> 0 | G23: =BaseItem!$G$3+20 -> 20 | H23: =BaseItem!$H$3+15% -> 0.15 | I23: =BaseItem!$I$3+20% -> 0.2 | J23: =BaseItem!$J$3 -> 1 | K23: =BaseItem!$K$3 -> 0 | L23: =BaseItem!$L$3 -> 0 | M23: =BaseItem!$M$3 -> 0 | N23: 3
B24: Thief's Gloves | C24: =BaseItem!$C$3+150 -> 150 | D24: =BaseItem!$D$3 -> 0 | E24: =BaseItem!$E$3 -> 0 | F24: =BaseItem!$F$3 -> 0 | G24: =BaseItem!$G$3 -> 0 | H24: =BaseItem!$H$3 -> 0 | I24: =BaseItem!$I$3+20% -> 0.2 | J24: =BaseItem!$J$3+10% -> 1.1 | K24: =BaseItem!$K$3 -> 0 | L24: =BaseItem!$L$3 -> 0 | M24: =BaseItem!$M$3 -> 0 | N24: 4
B25: Sterak's Gage | C25: =BaseItem!$C$3+300 -> 300 | D25: =BaseItem!$D$3+40 -> 40 | E25: =BaseItem!$E$3 -> 0 | F25: =BaseItem!$F$3 -> 0 | G25: =BaseItem!$G$3 -> 0 | H25: =BaseItem!$H$3 -> 0 | I25: =BaseItem!$I$3 -> 0 | J25: =BaseItem!$J$3 -> 1 | K25: =BaseItem!$K$3 -> 0 | L25: =BaseItem!$L$3 -> 0 | M25: =BaseItem!$M$3 -> 0 | N25: 4
B26: Protector's Vow | C26: =BaseItem!$C$3+150 -> 150 | D26: =BaseItem!$D$3 -> 0 | E26: =BaseItem!$E$3 -> 0 | F26: =BaseItem!$F$3+25 -> 25 | G26: =BaseItem!$G$3+25 -> 25 | H26: =BaseItem!$H$3 -> 0 | I26: =BaseItem!$I$3 -> 0 | J26: =BaseItem!$J$3 -> 1 | K26: =BaseItem!$K$3 -> 0 | L26: =BaseItem!$L$3 -> 0 | M26: =BaseItem!$M$3 -> 0 | N26: 4
B27: Gargoyle Stoneplate | C27: =BaseItem!$C$3+100 -> 100 | D27: =BaseItem!$D$3 -> 0 | E27: =BaseItem!$E$3 -> 0 | F27: =BaseItem!$F$3+35 -> 35 | G27: =BaseItem!$G$3+35 -> 35 | H27: =BaseItem!$H$3 -> 0 | I27: =BaseItem!$I$3 -> 0 | J27: =BaseItem!$J$3 -> 1 | K27: =BaseItem!$K$3 -> 0 | L27: =BaseItem!$L$3 -> 0 | M27: =BaseItem!$M$3 -> 0 | N27: 4
B28: Evenshroud | C28: =BaseItem!$C$3+150 -> 150 | D28: =BaseItem!$D$3 -> 0 | E28: =BaseItem!$E$3 -> 0 | F28: =BaseItem!$F$3 -> 0 | G28: =BaseItem!$G$3+45 -> 45 | H28: =BaseItem!$H$3 -> 0 | I28: =BaseItem!$I$3 -> 0 | J28: =BaseItem!$J$3 -> 1 | K28: =BaseItem!$K$3 -> 0 | L28: =BaseItem!$L$3 -> 0 | M28: =BaseItem!$M$3 -> 0 | N28: 4
B29: Steadfast Heart | C29: =BaseItem!$C$3+150 -> 150 | D29: =BaseItem!$D$3 -> 0 | E29: =BaseItem!$E$3 -> 0 | F29: =BaseItem!$F$3+20 -> 20 | G29: =BaseItem!$G$3 -> 0 | H29: =BaseItem!$H$3 -> 0 | I29: =BaseItem!$I$3+20% -> 0.2 | J29: =BaseItem!$J$3 -> 1 | K29: =BaseItem!$K$3 -> 0 | L29: =BaseItem!$L$3 -> 0 | M29: =BaseItem!$M$3+18% -> 0.18 | N29: 4
B30: Sunfire Cape | C30: =BaseItem!$C$3+250 -> 250 | D30: =BaseItem!$D$3 -> 0 | E30: =BaseItem!$E$3 -> 0 | F30: =BaseItem!$F$3+25 -> 25 | G30: =BaseItem!$G$3 -> 0 | H30: =BaseItem!$H$3 -> 0 | I30: =BaseItem!$I$3 -> 0 | J30: =BaseItem!$J$3 -> 1 | K30: =BaseItem!$K$3 -> 0 | L30: =BaseItem!$L$3 -> 0 | M30: =BaseItem!$M$3 -> 0 | N30: 4
B31: Warmog's Armor | C31: =BaseItem!$C$3+750 -> 750 | D31: =BaseItem!$D$3 -> 0 | E31: =BaseItem!$E$3 -> 0 | F31: =BaseItem!$F$3 -> 0 | G31: =BaseItem!$G$3 -> 0 | H31: =BaseItem!$H$3 -> 0 | I31: =BaseItem!$I$3 -> 0 | J31: =BaseItem!$J$3 -> 1 | K31: =BaseItem!$K$3 -> 0 | L31: =BaseItem!$L$3 -> 0 | M31: =BaseItem!$M$3 -> 0 | N31: 4
B32: Spirit Visage | C32: =BaseItem!$C$3+300 -> 300 | D32: =BaseItem!$D$3 -> 0 | E32: =BaseItem!$E$3 -> 0 | F32: =BaseItem!$F$3 -> 0 | G32: =BaseItem!$G$3 -> 0 | H32: =BaseItem!$H$3 -> 0 | I32: =BaseItem!$I$3 -> 0 | J32: =BaseItem!$J$3 -> 1 | K32: =BaseItem!$K$3 -> 0 | L32: =BaseItem!$L$3 -> 0 | M32: =BaseItem!$M$3+10% -> 0.1 | N32: 4
B33: Bramble Vest | C33: =BaseItem!$C$3 -> 0 | D33: =BaseItem!$D$3 -> 0 | E33: =BaseItem!$E$3 -> 0 | F33: =BaseItem!$F$3+65 -> 65 | G33: =BaseItem!$G$3 -> 0 | H33: =BaseItem!$H$3 -> 0 | I33: =BaseItem!$I$3 -> 0 | J33: =BaseItem!$J$3 -> 1 | K33: =BaseItem!$K$3 -> 0 | L33: =BaseItem!$L$3 -> 0 | M33: =BaseItem!$M$3+8% -> 0.08 | N33: 4
B34: Adaptive Helm | C34: =BaseItem!$C$3 -> 0 | D34: =BaseItem!$D$3 -> 0 | E34: =BaseItem!$E$3 -> 0 | F34: =BaseItem!$F$3+35 -> 35 | G34: =BaseItem!$G$3+55 -> 55 | H34: =BaseItem!$H$3 -> 0 | I34: =BaseItem!$I$3 -> 0 | J34: =BaseItem!$J$3 -> 1 | K34: =BaseItem!$K$3 -> 0 | L34: =BaseItem!$L$3 -> 0 | M34: =BaseItem!$M$3 -> 0 | N34: 4
B35: Crownguard | C35: 100 | D35: =BaseItem!$D$3 -> 0 | E35: =BaseItem!$E$3+20 -> 20 | F35: =BaseItem!$F$3+20 -> 20 | G35: =BaseItem!$G$3 -> 0 | H35: =BaseItem!$H$3 -> 0 | I35: =BaseItem!$I$3 -> 0 | J35: =BaseItem!$J$3 -> 1 | K35: =BaseItem!$K$3 -> 0 | L35: =BaseItem!$L$3 -> 0 | M35: =BaseItem!$M$3 -> 0 | N35: 4
B36: Ionic Spark | C36: =BaseItem!$C$3+250 -> 250 | D36: =BaseItem!$D$3 -> 0 | E36: =BaseItem!$E$3+15 -> 15 | F36: =BaseItem!$F$3 -> 0 | G36: =BaseItem!$G$3+35 -> 35 | H36: =BaseItem!$H$3 -> 0 | I36: =BaseItem!$I$3 -> 0 | J36: =BaseItem!$J$3 -> 1 | K36: =BaseItem!$K$3 -> 0 | L36: =BaseItem!$L$3 -> 0 | M36: =BaseItem!$M$3 -> 0 | N36: 4
B37: Dragon's Claw | C37: =BaseItem!$C$3 -> 0 | D37: =BaseItem!$D$3 -> 0 | E37: =BaseItem!$E$3 -> 0 | F37: =BaseItem!$F$3 -> 0 | G37: =BaseItem!$G$3+75 -> 75 | H37: =BaseItem!$H$3 -> 0 | I37: =BaseItem!$I$3 -> 0 | J37: =BaseItem!$J$3 -> 1 | K37: =BaseItem!$K$3 -> 0 | L37: =BaseItem!$L$3 -> 0 | M37: =BaseItem!$M$3+8% -> 0.08 | N37: 4
B38: Titan's Resolve | C38: =BaseItem!$C$3 -> 0 | D38: =BaseItem!$D$3+15 -> 15 | E38: =BaseItem!$E$3+15 -> 15 | F38: =BaseItem!$F$3+15 -> 15 | G38: =BaseItem!$G$3+15 -> 15 | H38: =BaseItem!$H$3+10% -> 0.1 | I38: =BaseItem!$I$3 -> 0 | J38: =BaseItem!$J$3 -> 1 | K38: =BaseItem!$K$3 -> 0 | L38: =BaseItem!$L$3 -> 0 | M38: =BaseItem!$M$3 -> 0 | N38: 4
B40: Item Type Leyend
C41: Physical Damage (AD)
...

Sheet Calculator
E2: EQUIPMENT SELECTOR
E3: Champion | F3: Items | G3: Enemy | H3: Items
E4: Renekton | F4: Spear of Shojin | G4: Draven | H4: Titan's Resolve
F5: Edge of Night | H5: Dragon's Claw
F6: Titan's Resolve | H6: Bloodthirster
E8: Chose a champion and equipt it with 3 items! | G8: you can use the visual guides on the Items and Champions sheets to know which items suit best your champion
E11: Ally | G11: Enemy
E12: Champion | F12: C. Item | G12: Enemy | H12: Enemy Items | I12: Final Stats Ally | J12: Final Stats Enemy
C13: STATS | D13: Health | E13: =VLOOKUP($E$4,Champions!$B$3:$M$17,2,FALSE) -> 450 | F13: =VLOOKUP($F$4,Items!$B$3:$M$38,2,FALSE)+VLOOKUP($F$5,Items!$B$3:$M$38,2,FALSE)+VLOOKUP($F$6,Items!$B$3:$M$38,2,FALSE) -> 0 | G13: =VLOOKUP($G$4,Champions!$B$3:$M$13,2,FALSE) -> 350 | H13: =VLOOKUP($H$4,Items!$B$3:$M$38,2,FALSE)+VLOOKUP($H$5,Items!$B$3:$M$38,2,FALSE)+VLOOKUP($H$6,Items!$B$3:$M$38,2,FALSE) -> 0 | I13: =E13+F13 -> 450 | J13: =G13+H13 -> 350
D14: Attack Damage | E14: =VLOOKUP($E$4,Champions!$B$3:$M$17,3,FALSE) -> 45 | F14: =VLOOKUP($F$4,Items!$B$3:$M$38,3,FALSE)+VLOOKUP($F$5,Items!$B$3:$M$38,3,FALSE)+VLOOKUP($F$6,Items!$B$3:$M$38,3,FALSE) -> 40 | G14: =VLOOKUP($G$4,Champions!$B$3:$M$13,3,FALSE) -> 70 | H14: =VLOOKUP($H$4,Items!$B$3:$M$38,3,FALSE)+VLOOKUP($H$5,Items!$B$3:$M$38,3,FALSE)+VLOOKUP($H$6,Items!$B$3:$M$38,3,FALSE) -> 35 | I14: =E14+F14 -> 85 | J14: =G14+H14 -> 105
D15: Ability Power | E15: =VLOOKUP($E$4,Champions!$B$3:$M$17,4,FALSE) -> 0 | F15: =VLOOKUP($F$4,Items!$B$3:$M$38,4,FALSE)+VLOOKUP($F$5,Items!$B$3:$M$38,4,FALSE)+VLOOKUP($F$6,Items!$B$3:$M$38,4,FALSE) -> 35 | G15: =VLOOKUP($G$4,Champions!$B$3:$M$13,4,FALSE) -> 0 | H15: =VLOOKUP($H$4,Items!$B$3:$M$38,4,FALSE)+VLOOKUP($H$5,Items!$B$3:$M$38,4,FALSE)+VLOOKUP($H$6,Items!$B$3:$M$38,4,FALSE) -> 35 | I15: =E15+F15 -> 35 | J15: =G15+H15 -> 35
D16: Armor | E16: =VLOOKUP($E$4,Champions!$B$3:$M$17,5,FALSE) -> 20 | F16: =VLOOKUP($F$4,Items!$B$3:$M$38,5,FALSE)+VLOOKUP($F$5,Items!$B$3:$M$38,5,FALSE)+VLOOKUP($F$6,Items!$B$3:$M$38,5,FALSE) -> 35 | G16: =VLOOKUP($G$4,Champions!$B$3:$M$13,5,FALSE) -> 10 | H16: =VLOOKUP($H$4,Items!$B$3:$M$38,5,FALSE)+VLOOKUP($H$5,Items!$B$3:$M$38,5,FALSE)+VLOOKUP($H$6,Items!$B$3:$M$38,5,FALSE) -> 15 | I16: =E16+F16 -> 55 | J16: =G16+H16 -> 25
D17: Magic Resist | E17: =VLOOKUP($E$4,Champions!$B$3:$M$17,6,FALSE) -> 20 | F17: =VLOOKUP($F$4,Items!$B$3:$M$38,6,FALSE)+VLOOKUP($F$5,Items!$B$3:$M$38,6,FALSE)+VLOOKUP($F$6,Items!$B$3:$M$38,6,FALSE) -> 15 | G17: =VLOOKUP($G$4,Champions!$B$3:$M$13,6,FALSE) -> 10 | H17: =VLOOKUP($H$4,Items!$B$3:$M$38,6,FALSE)+VLOOKUP($H$5,Items!$B$3:$M$38,6,FALSE)+VLOOKUP($H$6,Items!$B$3:$M$38,6,FALSE) -> 110 | I17: =E17+F17 -> 35 | J17: =G17+H17 -> 120
D18: Attack Speed | E18: =VLOOKUP($E$4,Champions!$B$3:$M$17,7,FALSE) -> 0.65 | F18: =VLOOKUP($F$4,Items!$B$3:$M$38,7,FALSE)+VLOOKUP($F$5,Items!$B$3:$M$38,7,FALSE)+VLOOKUP($F$6,Items!$B$3:$M$38,7,FALSE) -> 0.25 | G18: =VLOOKUP($G$4,Champions!$B$3:$M$13,7,FALSE) -> 0.75 | H18: =VLOOKUP($H$4,Items!$B$3:$M$38,7,FALSE)+VLOOKUP($H$5,Items!$B$3:$M$38,7,FALSE)+VLOOKUP($H$6,Items!$B$3:$M$38,7,FALSE) -> 0.1 | I18: =E18+F18 -> 0.9 | J18: =G18+H18 -> 0.85
D19: Critical Strike Chance | E19: =VLOOKUP($E$4,Champions!$B$3:$M$17,8,FALSE) -> 0.25 | F19: =VLOOKUP($F$4,Items!$B$3:$M$38,8,FALSE)+VLOOKUP($F$5,Items!$B$3:$M$38,8,FALSE)+VLOOKUP($F$6,Items!$B$3:$M$38,8,FALSE) -> 0 | G19: =VLOOKUP($G$4,Champions!$B$3:$M$13,8,FALSE) -> 0.25 | H19: =VLOOKUP($H$4,Items!$B$3:$M$38,8,FALSE)+VLOOKUP($H$5,Items!$B$3:$M$38,8,FALSE)+VLOOKUP($H$6,Items!$B$3:$M$38,8,FALSE) -> 0 | I19: =E19+F19 -> 0.25 | J19: =G19+H19 -> 0.25
D20: Critical Strike Damage | E20: =VLOOKUP($E$4,Champions!$B$3:$M$17,9,FALSE) -> 0 | F20: =VLOOKUP($F$4,Items!$B$3:$M$38,9,FALSE)+VLOOKUP($F$5,Items!$B$3:$M$38,9,FALSE)+VLOOKUP($F$6,Items!$B$3:$M$38,9,FALSE) -> 3 | G20: =VLOOKUP($G$4,Champions!$B$3:$M$13,9,FALSE) -> 0 | H20: =VLOOKUP($H$4,Items!$B$3:$M$38,9,FALSE)+VLOOKUP($H$5,Items!$B$3:$M$38,9,FALSE)+VLOOKUP($H$6,Items!$B$3:$M$38,9,FALSE) -> 3 | I20: =E20+F20 -> 3 | J20: =G20+H20 -> 3
D21: Omnivamp | E21: =VLOOKUP($E$4,Champions!$B$3:$M$17,10,FALSE) -> 0 | F21: =VLOOKUP($F$4,Items!$B$3:$M$38,10,FALSE)+VLOOKUP($F$5,Items!$B$3:$M$38,10,FALSE)+VLOOKUP($F$6,Items!$B$3:$M$38,10,FALSE) -> 0 | G21: =VLOOKUP($G$4,Champions!$B$3:$M$13,10,FALSE) -> 0 | H21: =VLOOKUP($H$4,Items!$B$3:$M$38,10,FALSE)+VLOOKUP($H$5,Items!$B$3:$M$38,10,FALSE)+VLOOKUP($H$6,Items!$B$3:$M$38,10,FALSE) -> 0.2 | I21: =E21+F21 -> 0 | J21: =G21+H21 -> 0.2
D22: Durability | E22: =VLOOKUP($E$4,Champions!$B$3:$M$17,11,FALSE) -> 0 | F22: =VLOOKUP($F$4,Items!$B$3:$M$38,11,FALSE)+VLOOKUP($F$5,Items!$B$3:$M$38,11,FALSE)+VLOOKUP($F$6,Items!$B$3:$M$38,11,FALSE) -> 0.1 | G22: =VLOOKUP($G$4,Champions!$B$3:$M$13,11,FALSE) -> 0 | H22: =VLOOKUP($H$4,Items!$B$3:$M$38,11,FALSE)+VLOOKUP($H$5,Items!$B$3:$M$38,11,FALSE)+VLOOKUP($H$6,Items!$B$3:$M$38,11,FALSE) -> 0 | I22: =E22+F22 -> 0.1 | J22: =G22+H22 -> 0
D23: Damage Amp. | E23: =VLOOKUP($E$4,Champions!$B$3:$M$17,12,FALSE) -> 0 | F23: =VLOOKUP($F$4,Items!$B$3:$M$38,12,FALSE)+VLOOKUP($F$5,Items!$B$3:$M$38,12,FALSE)+VLOOKUP($F$6,Items!$B$3:$M$38,12,FALSE) -> 0 | G23: =VLOOKUP($G$4,Champions!$B$3:$M$13,12,FALSE) -> 0 | H23: =VLOOKUP($H$4,Items!$B$3:$M$38,12,FALSE)+VLOOKUP($H$5,Items!$B$3:$M$38,12,FALSE)+VLOOKUP($H$6,Items!$B$3:$M$38,12,FALSE) -> 0.08 | I23: =E23+F23 -> 0 | J23: =G23+H23 -> 0.08
E25: Ally | F25: Enemy
D26: Crit Factor | E26: =(1-$I$19)*(1+$I$19)*$I$20 -> 2.8125 | F26: =(1-J19)*(1+J19)*J20 -> 2.8125
H28: DAMAGE CALCULATION FORMULA
E29: Ally | F29: Enemy | H29: =(((AD*AD_Scaling*AS) * IF(RAND()<CriticalStrikeChance, CriticalStrikeDamage, 1))/(1+Armor/100)
D30: Final Damage | E30: =(((Calculator!I14*VLOOKUP(E4,Champions!B3:P15,14,FALSE)*Calculator!I18)*(IF(RAND()<Calculator!I19,Calculator!I20,1)/(1+Calculator!J16/100)+(Calculator!I15*VLOOKUP(E4,Champions!B3:P15,15,FALSE))/(1+Calculator!J17/100)*(1+Calculator!I23)/(1+Calculator!J22)))) -> 106.61318 | F30: =(((J14*VLOOKUP(Calculator!G4,Champions!B3:P15,14,FALSE)*Calculator!J18)*IF(RAND()<Calculator!J19,Calculator!J20*1))/(1+Calculator!I16/100)+(Calculator!J15*VLOOKUP(Calculator!G4,Champions!B3:P15,15,FALSE))/(1+Calculator!I17/100)*(1+Calculator!J23)/(1+Calculator!I22)) -> 1.2727273 | H30: + (AP*AP_Scaling)/(1+MR/100)) * (1+DamageAmp) / (1+Durability/100)
D31: Omnivamp | E31: =E30*I21 -> 0 | F31: =F30*J21 -> 0.25454545
D32: Final Health | E32: =I13-F30+E31 -> 448.72727 | F32: =J13-E30+F31 -> 243.64136
D35: COMBAT TURN SIMULATION
D37: Turn | E37: Attacker | F37: Damage | G37: Ally HP | H37: Enemy HP | J37: Winner | K37: {=INDEX($E$38:$E$117,MATCH(TRUE,($G$38:$G$117<=0)+($H$38:$H$117<=0)>0,0))} -> Ally
D38: 1 | E38: Ally | F38: =$E$30 -> 106.61318 | G38: =E32 -> 448.72727 | H38: =F32 -> 243.64136
D39: 2 | E39: Enemy | F39: =$F$30 -> 1.2727273 | G39: =$G38-$F39+$E$31 -> 447.45455 | H39: =$H38 -> 243.64136
D40: 3 | E40: Ally | F40: =$E$30 -> 106.61318 | G40: =$G39 -> 447.45455 | H40: =$H39-$F40+$F$31 -> 137.28273
D41: 4 | E41: Enemy | F41: =$F$30 -> 1.2727273 | G41: =$G40-$F41+$E$31 -> 446.18182 | H41: =$H40 -> 137.28273
D42: 5 | E42: Ally | F42: =$E$30 -> 106.61318 | G42: =$G41 -> 446.18182 | H42: =$H41-$F41+$F$31 -> 136.26455
D43: 6 | E43: Enemy | F43: =$F$30 -> 1.2727273 | G43: =$G42-$F43+$E$31 -> 444.90909 | H43: =$H42 -> 136.26455
D44: 7 | E44: Ally | F44: =$E$30 -> 106.61318 | G44: =$G43 -> 444.90909 | H44: =$H43-$F44+$F$31 -> 29.905909
D45: 8 | E45: Enemy | F45: =$F$30 -> 1.2727273 | G45: =$G44-$F45+$E$31 -> 443.63636 | H45: =$H44 -> 29.905909
D46: 9 | E46: Ally | F46: =$E$30 -> 106.61318 | G46: =$G45 -> 443.63636 | H46: =$H45-$F45+$F$31 -> 28.887727
D47: 10 | E47: Enemy | F47: =$F$30 -> 1.2727273 | G47: =$G46-$F47+$E$31 -> 442.36364 | H47: =$H46 -> 28.887727
D48: 11 | E48: Ally | F48: =$E$30 -> 106.61318 | G48: =$G47 -> 442.36364 | H48: =$H47-$F48+$F$31 -> -77.470909
D49: 12 | E49: Enemy | F49: =$F$30 -> 1.2727273 | G49: =$G48-$F49+$E$31 -> 441.09091 | H49: =$H48 -> -77.470909
...

Sheet Lists
B3: Champion | C3: Type | D3: Items
B4: =Champions!$B3 -> Jayce | C4: Ally | D4: =Items!$B3 -> Spear of Shojin
B5: =Champions!$B4 -> Janna | C5: Enemy | D5: =Items!$B4 -> Kraken's Fury
B6: =Champions!$B5 -> Dr.Mundo | D6: =Items!$B5 -> Infinity Edge
B7: =Champions!$B6 -> Azir | D7: =Items!$B6 -> Giant Slayer
B8: =Champions!$B7 -> Poppy | D8: =Items!$B7 -> Edge of Night
B9: =Champions!$B8 -> Draven | D9: =Items!$B8 -> Deathblade
B10: =Champions!$B9 -> Katarina | D10: =Items!$B9 -> Bloodthirster
B11: =Champions!$B10 -> Kog'Maw | D11: =Items!$B10 -> Morellonomicon
B12: =Champions!$B11 -> Seraphine | D12: =Items!$B11 -> Void Staff
B13: =Champions!$B12 -> Renekton | D13: =Items!$B12 -> Blue Buff
B14: =Champions!$B13 -> Rakan | D14: =Items!$B13 -> Jewled Gauntlet
D15: =Items!$B14 -> Rabadon's Deathcap
D16: =Items!$B15 -> Hand of Justice
D17: =Items!$B16 -> Arcangel's Staff
D18: =Items!$B17 -> Hextech Gunblade
D19: =Items!$B18 -> Striker's Flail
D20: =Items!$B19 -> Red Buff
D21: =Items!$B20 -> Nashor's Tooth
D22: =Items!$B21 -> Guinsoo's Rageblade
D23: =Items!$B22 -> Last Whisper
D24: =Items!$B23 -> Quicksilver
D25: =Items!$B24 -> Thief's Gloves
D26: =Items!$B25 -> Sterak's Gage
... D39: =Items!$B38 -> Titan's Resolve
